<?xml version="1.0" ?>
<robot xmlns:xacro="http://www.ros.org/wiki/xacro">
<!-- =================================================================================== -->
<!-- |    This document was autogenerated by xacro from /home/darkhorse/ros2_ws/src/robotic_arm/description/urdf/robotic_arm.urdf.xacro | -->
<!-- |    EDITING THIS FILE BY HAND IS NOT RECOMMENDED                                 | -->
<!-- =================================================================================== -->
<!-- This URDF was automatically created by SolidWorks to URDF Exporter! Originally created by Stephen Brawner (brawner@gmail.com) 
     Commit Version: 1.6.0-4-g7f85cfe  Build Version: 1.6.7995.38578
     For more information, please see http://wiki.ros.org/sw_urdf_exporter -->
  <link name = "world"/>

  <joint name = "base_joint" type = "fixed">
    <parent link = "world"/>
    <child link = "base_link"/>
    <origin rpy = "0 0 0" xyz = "0.0 0.0 0.0"/>
  </joint>

  <link name="base_link">
    <inertial>
      <origin rpy="0 0 0" xyz="0.073069 0.13264 0.2225"/>
      <mass value="1.5086"/>
      <inertia ixx="0.0043061" ixy="-2.3844E-07" ixz="-7.3077E-05" iyy="0.0080514" iyz="2.3844E-07" izz="0.0043061"/>
    </inertial>
    <visual>
      <origin rpy="0 0 0" xyz="0 0 0"/>
      <geometry>
        <mesh filename="package://robotic_arm/meshes/base_link.STL"/>
      </geometry>
      <material name="">
        <color rgba="0.79216 0.81961 0.93333 1"/>
      </material>
    </visual>
    <collision>
      <origin rpy="0 0 0" xyz="0 0 0"/>
      <geometry>
        <mesh filename="package://robotic_arm/meshes/base_link.STL"/>
      </geometry>
    </collision>
  </link>
  <link name="link_1">
    <inertial>
      <origin rpy="0 0 0" xyz="-0.057487 0.078405 0.0039341"/>
      <mass value="1.3333"/>
      <inertia ixx="0.0050949" ixy="0.0043173" ixz="0.00028916" iyy="0.00711" iyz="-0.00025095" izz="0.010704"/>
    </inertial>
    <visual>
      <origin rpy="0 0 0" xyz="0 0 0"/>
      <geometry>
        <mesh filename="package://robotic_arm/meshes/link_1.STL"/>
      </geometry>
      <material name="">
        <color rgba="0.69412 0.098039 0.098039 1"/>
      </material>
    </visual>
    <collision>
      <origin rpy="0 0 0" xyz="0 0 0"/>
      <geometry>
        <mesh filename="package://robotic_arm/meshes/link_1.STL"/>
      </geometry>
    </collision>
  </link>
  <joint name="joint_1" type="revolute">
    <origin rpy="1.5708 0 0" xyz="0.072332 -0.22324 0.16099"/>
    <parent link="base_link"/>
    <child link="link_1"/>
    <axis xyz="0 1 0"/>
    <limit effort="300" lower="0" upper="3.142" velocity="3"/>
  </joint>
  <link name="link_2">
    <inertial>
      <origin rpy="0 0 0" xyz="-0.14941 0.034282 0.0094769"/>
      <mass value="1.0447"/>
      <inertia ixx="0.00068419" ixy="-1.9061E-05" ixz="0.00023629" iyy="0.019048" iyz="2.1777E-05" izz="0.018654"/>
    </inertial>
    <visual>
      <origin rpy="0 0 0" xyz="0 0 0"/>
      <geometry>
        <mesh filename="package://robotic_arm/meshes/link_2.STL"/>
      </geometry>
      <material name="">
        <color rgba="0.69412 0.098039 0.098039 1"/>
      </material>
    </visual>
    <collision>
      <origin rpy="0 0 0" xyz="0 0 0"/>
      <geometry>
        <mesh filename="package://robotic_arm/meshes/link_2.STL"/>
      </geometry>
    </collision>
  </link>
  <joint name="joint_2" type="revolute">
    <origin rpy="-1.5708 0 -2.4026" xyz="-0.1461 0.15286 -0.0075"/>
    <parent link="link_1"/>
    <child link="link_2"/>
    <axis xyz="0 -1 0"/>
    <limit effort="200" lower="-1.57" upper="1.57" velocity="3"/>
  </joint>
  <link name="link_3">
    <inertial>
      <origin rpy="0 0 0" xyz="0.026725 -0.04057 -0.11374"/>
      <mass value="1.9528"/>
      <inertia ixx="0.010186" ixy="0.00012722" ixz="0.00011585" iyy="0.0098947" iyz="-0.0004026" izz="0.002441"/>
    </inertial>
    <visual>
      <origin rpy="0 0 0" xyz="0 0 0"/>
      <geometry>
        <mesh filename="package://robotic_arm/meshes/link_3.STL"/>
      </geometry>
      <material name="">
        <color rgba="0.79216 0.81961 0.93333 1"/>
      </material>
    </visual>
    <collision>
      <origin rpy="0 0 0" xyz="0 0 0"/>
      <geometry>
        <mesh filename="package://robotic_arm/meshes/link_3.STL"/>
      </geometry>
    </collision>
  </link>
  <joint name="joint_3" type="revolute">
    <origin rpy="0.7381 0 -1.5708" xyz="-0.35 0 0"/>
    <parent link="link_2"/>
    <child link="link_3"/>
    <axis xyz="-1 0 0"/>
    <limit effort="200" lower="0" upper="3.142" velocity="3"/>
  </joint>
  <link name="link_4">
    <inertial>
      <origin rpy="0 0 0" xyz="0.020252 0.0098033 0.066456"/>
      <mass value="0.41784"/>
      <inertia ixx="0.00044426" ixy="3.2023E-07" ixz="-1.7104E-19" iyy="0.00044991" iyz="2.2175E-19" izz="0.00028178"/>
    </inertial>
    <visual>
      <origin rpy="0 0 0" xyz="0 0 0"/>
      <geometry>
        <mesh filename="package://robotic_arm/meshes/link_4.STL"/>
      </geometry>
      <material name="">
        <color rgba="0.69412 0.098039 0.098039 1"/>
      </material>
    </visual>
    <collision>
      <origin rpy="0 0 0" xyz="0 0 0"/>
      <geometry>
        <mesh filename="package://robotic_arm/meshes/link_4.STL"/>
      </geometry>
    </collision>
  </link>
  <joint name="joint_4" type="revolute">
    <origin rpy="-1.5026 -0.44991 -0.029688" xyz="0 -0.045 -0.361"/>
    <parent link="link_3"/>
    <child link="link_4"/>
    <axis xyz="-0.90009 -0.4357 0"/>
    <limit effort="200" lower="0" upper="3.142" velocity="3"/>
  </joint>
  <link name="gripper_1">
    <inertial>
      <origin rpy="0 0 0" xyz="0.015716 -0.0097903 0.051506"/>
      <mass value="0.037969"/>
      <inertia ixx="4.3999E-05" ixy="-1.9125E-09" ixz="-9.3039E-06" iyy="4.8118E-05" iyz="-6.1689E-09" izz="6.21E-06"/>
    </inertial>
    <visual>
      <origin rpy="0 0 0" xyz="0 0 0"/>
      <geometry>
        <mesh filename="package://robotic_arm/meshes/gripper_1.STL"/>
      </geometry>
      <material name="">
        <color rgba="0.2 0.2 0.2 1"/>
      </material>
    </visual>
    <collision>
      <origin rpy="0 0 0" xyz="0 0 0"/>
      <geometry>
        <mesh filename="package://robotic_arm/meshes/gripper_1.STL"/>
      </geometry>
    </collision>
  </link>
  <joint name="joint_5" type="revolute">
    <origin rpy="0 0.40032 -3.1416" xyz="0.061613 0 0.12535"/>
    <parent link="link_4"/>
    <child link="gripper_1"/>
    <axis xyz="0 1 0"/>
    <limit effort="200" lower="-0.785" upper="0.785" velocity="3"/>
  </joint>
  <link name="gripper_2">
    <inertial>
      <origin rpy="0 0 0" xyz="0.015716 0.0098163 0.051506"/>
      <mass value="0.037969"/>
      <inertia ixx="4.3999E-05" ixy="-1.9125E-09" ixz="-9.3039E-06" iyy="4.8118E-05" iyz="-6.1689E-09" izz="6.21E-06"/>
    </inertial>
    <visual>
      <origin rpy="0 0 0" xyz="0 0 0"/>
      <geometry>
        <mesh filename="package://robotic_arm/meshes/gripper_2.STL"/>
      </geometry>
      <material name="">
        <color rgba="0.2 0.2 0.2 1"/>
      </material>
    </visual>
    <collision>
      <origin rpy="0 0 0" xyz="0 0 0"/>
      <geometry>
        <mesh filename="package://robotic_arm/meshes/gripper_2.STL"/>
      </geometry>
    </collision>
  </link>
  <joint name="joint_6" type="revolute">
    <origin rpy="0 -0.55041 0" xyz="-0.021108 0 0.12535"/>
    <parent link="link_4"/>
    <child link="gripper_2"/>
    <axis xyz="0 -1 0"/>
    <limit effort="200" lower="-0.785" upper="0.785" velocity="3"/>
  </joint>
</robot>
